2018-06-04 02:23:59 ERROR (Thread-7) [xiaomi_gateway] Cannot connect to Gateway
2018-06-04 02:23:59 ERROR (Thread-7) [xiaomi_gateway] No data in response from hub None
2018-06-04 02:24:30 ERROR (Thread-20) [xiaomi_gateway] Cannot connect to Gateway
2018-06-04 02:24:30 ERROR (Thread-20) [xiaomi_gateway] No data in response from hub None
2018-06-04 02:26:34 ERROR (Thread-22) [xiaomi_gateway] Cannot connect to Gateway
2018-06-04 02:26:34 ERROR (Thread-22) [xiaomi_gateway] No data in response from hub None
2018-06-04 02:27:05 ERROR (Thread-7) [xiaomi_gateway] Cannot connect to Gateway
2018-06-04 02:27:05 ERROR (Thread-7) [xiaomi_gateway] No data in response from hub None
2018-06-04 02:27:36 ERROR (Thread-16) [xiaomi_gateway] Cannot connect to Gateway
2018-06-04 02:27:36 ERROR (Thread-16) [xiaomi_gateway] No data in response from hub None
2018-06-04 02:28:07 ERROR (Thread-5) [xiaomi_gateway] Cannot connect to Gateway
2018-06-04 02:28:07 ERROR (Thread-5) [xiaomi_gateway] No data in response from hub None
2018-06-04 02:28:38 ERROR (Thread-14) [xiaomi_gateway] Cannot connect to Gateway
2018-06-04 02:28:38 ERROR (Thread-14) [xiaomi_gateway] No data in response from hub None
2018-06-04 02:29:12 ERROR (Thread-13) [xiaomi_gateway] Cannot connect to Gateway
2018-06-04 02:29:12 ERROR (Thread-13) [xiaomi_gateway] No data in response from hub None
2018-06-04 06:31:21 ERROR (Thread-16) [xiaomi_gateway] Cannot connect to Gateway
2018-06-04 06:31:21 ERROR (Thread-16) [xiaomi_gateway] No data in response from hub None
2018-06-04 07:35:56 ERROR (Thread-13) [xiaomi_gateway] Cannot connect to Gateway
2018-06-04 07:35:56 ERROR (Thread-13) [xiaomi_gateway] No data in response from hub None
2018-06-04 12:48:27 ERROR (Thread-19) [xiaomi_gateway] Cannot connect to Gateway
2018-06-04 12:48:27 ERROR (Thread-19) [xiaomi_gateway] No data in response from hub None
2018-06-04 12:52:35 ERROR (Thread-5) [xiaomi_gateway] Cannot connect to Gateway
2018-06-04 12:52:35 ERROR (Thread-5) [xiaomi_gateway] No data in response from hub None
2018-06-04 13:00:19 ERROR (Thread-21) [xiaomi_gateway] Cannot connect to Gateway
2018-06-04 13:00:19 ERROR (Thread-21) [xiaomi_gateway] No data in response from hub None
2018-06-04 13:54:33 ERROR (Thread-14) [xiaomi_gateway] Cannot connect to Gateway
2018-06-04 13:54:33 ERROR (Thread-14) [xiaomi_gateway] No data in response from hub None
2018-06-04 14:35:22 ERROR (Thread-15) [xiaomi_gateway] Cannot connect to Gateway
2018-06-04 14:35:22 ERROR (Thread-15) [xiaomi_gateway] No data in response from hub None
2018-06-04 15:14:06 ERROR (Thread-6) [xiaomi_gateway] Cannot connect to Gateway
2018-06-04 15:14:06 ERROR (Thread-6) [xiaomi_gateway] No data in response from hub None
2018-06-04 17:46:59 ERROR (Thread-21) [xiaomi_gateway] Cannot connect to Gateway
2018-06-04 17:46:59 ERROR (Thread-21) [xiaomi_gateway] No data in response from hub None
2018-06-04 18:52:05 ERROR (Thread-16) [xiaomi_gateway] Cannot connect to Gateway
2018-06-04 18:52:05 ERROR (Thread-16) [xiaomi_gateway] No data in response from hub None
2018-06-04 20:08:33 ERROR (Thread-16) [xiaomi_gateway] Cannot connect to Gateway
2018-06-04 20:08:33 ERROR (Thread-16) [xiaomi_gateway] No data in response from hub None
2018-06-04 20:20:57 ERROR (Thread-11) [xiaomi_gateway] Cannot connect to Gateway
2018-06-04 20:20:57 ERROR (Thread-11) [xiaomi_gateway] No data in response from hub None
2018-06-04 20:34:22 ERROR (Thread-22) [xiaomi_gateway] Cannot connect to Gateway
2018-06-04 20:34:22 ERROR (Thread-22) [xiaomi_gateway] No data in response from hub None
2018-06-04 20:46:15 ERROR (Thread-15) [xiaomi_gateway] Cannot connect to Gateway
2018-06-04 20:46:15 ERROR (Thread-15) [xiaomi_gateway] No data in response from hub None
2018-06-04 21:15:54 ERROR (MainThread) [homeassistant.components.telegram_bot.polling] wrong status 502
2018-06-04 22:14:36 ERROR (Thread-11) [xiaomi_gateway] Cannot connect to Gateway
2018-06-04 22:14:36 ERROR (Thread-11) [xiaomi_gateway] No data in response from hub None
2018-06-04 23:33:57 ERROR (MainThread) [homeassistant.components.light.hue] Unable to reach bridge 192.168.2.52
2018-06-04 23:34:08 ERROR (Thread-4) [xiaomi_gateway] Cannot connect to Gateway
2018-06-04 23:34:08 ERROR (Thread-4) [xiaomi_gateway] No data in response from hub None
2018-06-04 23:34:18 ERROR (Thread-9) [xiaomi_gateway] Cannot connect to Gateway
2018-06-04 23:34:18 ERROR (Thread-9) [xiaomi_gateway] No data in response from hub None
2018-06-04 23:35:30 ERROR (MainThread) [homeassistant.components.light.hue] Unable to reach bridge 192.168.2.52
2018-06-04 23:36:10 ERROR (MainThread) [homeassistant.helpers.entity] Update for media_player.osmc fails
Traceback (most recent call last):
  File "/srv/homeassistant/lib/python3.5/site-packages/jsonrpc_async/jsonrpc.py", line 29, in send_message
    response = yield from self._request(data=message.serialize())
  File "/srv/homeassistant/lib/python3.5/site-packages/aiohttp/client.py", line 333, in _request
    await resp.start(conn, read_until_eof)
  File "/srv/homeassistant/lib/python3.5/site-packages/aiohttp/client_reqrep.py", line 708, in start
    self._continue = None
  File "/srv/homeassistant/lib/python3.5/site-packages/aiohttp/helpers.py", line 670, in __exit__
    raise asyncio.TimeoutError from None
concurrent.futures._base.TimeoutError

During handling of the above exception, another exception occurred:

Traceback (most recent call last):
  File "/srv/homeassistant/lib/python3.5/site-packages/homeassistant/helpers/entity.py", line 204, in async_update_ha_state
    yield from self.async_device_update()
  File "/srv/homeassistant/lib/python3.5/site-packages/homeassistant/helpers/entity.py", line 325, in async_device_update
    yield from self.async_update()
  File "/srv/homeassistant/lib/python3.5/site-packages/homeassistant/components/media_player/kodi.py", line 454, in async_update
    ['time', 'totaltime', 'speed', 'live']
  File "/srv/homeassistant/lib/python3.5/site-packages/jsonrpc_async/jsonrpc.py", line 31, in send_message
    raise TransportError('Transport Error', message, exc)
jsonrpc_base.jsonrpc.TransportError: ("Error calling method 'Player.GetProperties': Transport Error", TimeoutError())
2018-06-04 23:36:43 ERROR (Thread-4) [xiaomi_gateway] Cannot connect to Gateway
2018-06-04 23:36:43 ERROR (Thread-4) [xiaomi_gateway] No data in response from hub None
2018-06-04 23:36:53 ERROR (Thread-3) [xiaomi_gateway] Cannot connect to Gateway
2018-06-04 23:36:53 ERROR (Thread-3) [xiaomi_gateway] No data in response from hub None
2018-06-04 23:37:34 ERROR (MainThread) [homeassistant.components.light.hue] Unable to reach bridge 192.168.2.52
2018-06-04 23:37:44 ERROR (MainThread) [homeassistant.helpers.entity] Update for media_player.osmc fails
Traceback (most recent call last):
  File "/srv/homeassistant/lib/python3.5/site-packages/jsonrpc_async/jsonrpc.py", line 29, in send_message
    response = yield from self._request(data=message.serialize())
  File "/srv/homeassistant/lib/python3.5/site-packages/aiohttp/client.py", line 333, in _request
    await resp.start(conn, read_until_eof)
  File "/srv/homeassistant/lib/python3.5/site-packages/aiohttp/client_reqrep.py", line 708, in start
    self._continue = None
  File "/srv/homeassistant/lib/python3.5/site-packages/aiohttp/helpers.py", line 670, in __exit__
    raise asyncio.TimeoutError from None
concurrent.futures._base.TimeoutError

During handling of the above exception, another exception occurred:

Traceback (most recent call last):
  File "/srv/homeassistant/lib/python3.5/site-packages/homeassistant/helpers/entity.py", line 204, in async_update_ha_state
    yield from self.async_device_update()
  File "/srv/homeassistant/lib/python3.5/site-packages/homeassistant/helpers/entity.py", line 325, in async_device_update
    yield from self.async_update()
  File "/srv/homeassistant/lib/python3.5/site-packages/homeassistant/components/media_player/kodi.py", line 444, in async_update
    ['volume', 'muted']
  File "/srv/homeassistant/lib/python3.5/site-packages/jsonrpc_async/jsonrpc.py", line 31, in send_message
    raise TransportError('Transport Error', message, exc)
jsonrpc_base.jsonrpc.TransportError: ("Error calling method 'Application.GetProperties': Transport Error", TimeoutError())
2018-06-04 23:37:45 ERROR (Thread-17) [xiaomi_gateway] Cannot connect to Gateway
2018-06-04 23:37:45 ERROR (Thread-17) [xiaomi_gateway] No data in response from hub None
2018-06-04 23:37:55 ERROR (Thread-16) [xiaomi_gateway] Cannot connect to Gateway
2018-06-04 23:37:55 ERROR (Thread-16) [xiaomi_gateway] No data in response from hub None
2018-06-04 23:41:22 ERROR (Thread-18) [xiaomi_gateway] Cannot connect to Gateway
2018-06-04 23:41:22 ERROR (Thread-18) [xiaomi_gateway] No data in response from hub None
2018-06-04 23:42:55 ERROR (Thread-4) [xiaomi_gateway] Cannot connect to Gateway
2018-06-04 23:42:55 ERROR (Thread-4) [xiaomi_gateway] No data in response from hub None
2018-06-04 23:43:14 ERROR (MainThread) [homeassistant.components.light.hue] Unable to reach bridge 192.168.2.52
2018-06-04 23:43:26 ERROR (Thread-15) [xiaomi_gateway] Cannot connect to Gateway
2018-06-04 23:43:26 ERROR (Thread-15) [xiaomi_gateway] No data in response from hub None
2018-06-04 23:43:57 ERROR (Thread-14) [xiaomi_gateway] Cannot connect to Gateway
2018-06-04 23:43:57 ERROR (Thread-14) [xiaomi_gateway] No data in response from hub None
2018-06-04 23:45:48 ERROR (MainThread) [homeassistant.helpers.entity] Update for media_player.osmc fails
Traceback (most recent call last):
  File "/srv/homeassistant/lib/python3.5/site-packages/jsonrpc_async/jsonrpc.py", line 29, in send_message
    response = yield from self._request(data=message.serialize())
  File "/srv/homeassistant/lib/python3.5/site-packages/aiohttp/client.py", line 333, in _request
    await resp.start(conn, read_until_eof)
  File "/srv/homeassistant/lib/python3.5/site-packages/aiohttp/client_reqrep.py", line 708, in start
    self._continue = None
  File "/srv/homeassistant/lib/python3.5/site-packages/aiohttp/helpers.py", line 670, in __exit__
    raise asyncio.TimeoutError from None
concurrent.futures._base.TimeoutError

During handling of the above exception, another exception occurred:

Traceback (most recent call last):
  File "/srv/homeassistant/lib/python3.5/site-packages/homeassistant/helpers/entity.py", line 204, in async_update_ha_state
    yield from self.async_device_update()
  File "/srv/homeassistant/lib/python3.5/site-packages/homeassistant/helpers/entity.py", line 325, in async_device_update
    yield from self.async_update()
  File "/srv/homeassistant/lib/python3.5/site-packages/homeassistant/components/media_player/kodi.py", line 454, in async_update
    ['time', 'totaltime', 'speed', 'live']
  File "/srv/homeassistant/lib/python3.5/site-packages/jsonrpc_async/jsonrpc.py", line 31, in send_message
    raise TransportError('Transport Error', message, exc)
jsonrpc_base.jsonrpc.TransportError: ("Error calling method 'Player.GetProperties': Transport Error", TimeoutError())
2018-06-04 23:45:49 ERROR (MainThread) [homeassistant.components.light.hue] Unable to reach bridge 192.168.2.52
