2018-06-02 03:36:40 ERROR (MainThread) [homeassistant.components.light.hue] Unable to reach bridge 192.168.2.52
2018-06-02 03:37:14 ERROR (Thread-10) [xiaomi_gateway] Cannot connect to Gateway
2018-06-02 03:37:14 ERROR (Thread-10) [xiaomi_gateway] No data in response from hub None
2018-06-02 03:37:19 ERROR (MainThread) [homeassistant.components.telegram_bot.polling] Cannot connect to host api.telegram.org:443 ssl:True [Temporary failure in name resolution]
2018-06-02 03:37:24 ERROR (Thread-2) [xiaomi_gateway] Cannot connect to Gateway
2018-06-02 03:37:24 ERROR (Thread-2) [xiaomi_gateway] No data in response from hub None
2018-06-02 03:37:45 ERROR (Thread-13) [xiaomi_gateway] Cannot connect to Gateway
2018-06-02 03:37:45 ERROR (Thread-13) [xiaomi_gateway] No data in response from hub None
2018-06-02 03:37:49 ERROR (MainThread) [homeassistant.components.telegram_bot.polling] Cannot connect to host api.telegram.org:443 ssl:True [Temporary failure in name resolution]
2018-06-02 03:37:55 ERROR (Thread-5) [xiaomi_gateway] Cannot connect to Gateway
2018-06-02 03:37:55 ERROR (Thread-5) [xiaomi_gateway] No data in response from hub None
2018-06-02 03:38:16 ERROR (Thread-9) [xiaomi_gateway] Cannot connect to Gateway
2018-06-02 03:38:16 ERROR (Thread-9) [xiaomi_gateway] No data in response from hub None
2018-06-02 03:38:19 ERROR (MainThread) [homeassistant.components.telegram_bot.polling] Cannot connect to host api.telegram.org:443 ssl:True [Temporary failure in name resolution]
2018-06-02 03:38:26 ERROR (Thread-4) [xiaomi_gateway] Cannot connect to Gateway
2018-06-02 03:38:26 ERROR (Thread-4) [xiaomi_gateway] No data in response from hub None
2018-06-02 03:38:47 ERROR (Thread-5) [xiaomi_gateway] Cannot connect to Gateway
2018-06-02 03:38:47 ERROR (Thread-5) [xiaomi_gateway] No data in response from hub None
2018-06-02 03:38:49 ERROR (MainThread) [homeassistant.components.telegram_bot.polling] Cannot connect to host api.telegram.org:443 ssl:True [Temporary failure in name resolution]
2018-06-02 03:38:57 ERROR (Thread-12) [xiaomi_gateway] Cannot connect to Gateway
2018-06-02 03:38:57 ERROR (Thread-12) [xiaomi_gateway] No data in response from hub None
2018-06-02 03:39:18 ERROR (Thread-4) [xiaomi_gateway] Cannot connect to Gateway
2018-06-02 03:39:18 ERROR (Thread-4) [xiaomi_gateway] No data in response from hub None
2018-06-02 03:39:19 ERROR (MainThread) [homeassistant.components.telegram_bot.polling] Cannot connect to host api.telegram.org:443 ssl:True [Temporary failure in name resolution]
2018-06-02 03:39:28 ERROR (Thread-14) [xiaomi_gateway] Cannot connect to Gateway
2018-06-02 03:39:28 ERROR (Thread-14) [xiaomi_gateway] No data in response from hub None
2018-06-02 03:39:29 ERROR (MainThread) [homeassistant.components.telegram_bot.polling] Cannot connect to host api.telegram.org:443 ssl:True [Temporary failure in name resolution]
2018-06-02 03:39:39 ERROR (MainThread) [homeassistant.helpers.entity] Update for binary_sensor.door_window_sensor_158d0001bf4ca9 fails
Traceback (most recent call last):
  File "/srv/homeassistant/lib/python3.5/site-packages/homeassistant/helpers/entity.py", line 204, in async_update_ha_state
    yield from self.async_device_update()
  File "/srv/homeassistant/lib/python3.5/site-packages/homeassistant/helpers/entity.py", line 327, in async_device_update
    yield from self.hass.async_add_job(self.update)
  File "/usr/lib/python3.5/asyncio/futures.py", line 380, in __iter__
    yield self  # This tells Task to wait for completion.
  File "/usr/lib/python3.5/asyncio/tasks.py", line 304, in _wakeup
    future.result()
  File "/usr/lib/python3.5/asyncio/futures.py", line 293, in result
    raise self._exception
  File "/usr/lib/python3.5/concurrent/futures/thread.py", line 55, in run
    result = self.fn(*self.args, **self.kwargs)
  File "/srv/homeassistant/lib/python3.5/site-packages/homeassistant/components/binary_sensor/xiaomi_aqara.py", line 90, in update
    self._get_from_hub(self._sid)
  File "/srv/homeassistant/lib/python3.5/site-packages/xiaomi_gateway/__init__.py", line 362, in get_from_hub
    resp = self._send_cmd(cmd, "read_ack") if int(self.proto[0:1]) == 1 else self._send_cmd(cmd, "read_rsp")
  File "/srv/homeassistant/lib/python3.5/site-packages/xiaomi_gateway/__init__.py", line 295, in _send_cmd
    self._socket.sendto(cmd.encode(), (self.ip_adress, self.port))
OSError: [Errno 101] Network is unreachable
2018-06-02 03:39:39 ERROR (MainThread) [homeassistant.helpers.entity] Update for binary_sensor.door_window_sensor_158d000200a8cd fails
Traceback (most recent call last):
  File "/srv/homeassistant/lib/python3.5/site-packages/homeassistant/helpers/entity.py", line 204, in async_update_ha_state
    yield from self.async_device_update()
  File "/srv/homeassistant/lib/python3.5/site-packages/homeassistant/helpers/entity.py", line 327, in async_device_update
    yield from self.hass.async_add_job(self.update)
  File "/usr/lib/python3.5/asyncio/futures.py", line 380, in __iter__
    yield self  # This tells Task to wait for completion.
  File "/usr/lib/python3.5/asyncio/tasks.py", line 304, in _wakeup
    future.result()
  File "/usr/lib/python3.5/asyncio/futures.py", line 293, in result
    raise self._exception
  File "/usr/lib/python3.5/concurrent/futures/thread.py", line 55, in run
    result = self.fn(*self.args, **self.kwargs)
  File "/srv/homeassistant/lib/python3.5/site-packages/homeassistant/components/binary_sensor/xiaomi_aqara.py", line 90, in update
    self._get_from_hub(self._sid)
  File "/srv/homeassistant/lib/python3.5/site-packages/xiaomi_gateway/__init__.py", line 362, in get_from_hub
    resp = self._send_cmd(cmd, "read_ack") if int(self.proto[0:1]) == 1 else self._send_cmd(cmd, "read_rsp")
  File "/srv/homeassistant/lib/python3.5/site-packages/xiaomi_gateway/__init__.py", line 295, in _send_cmd
    self._socket.sendto(cmd.encode(), (self.ip_adress, self.port))
OSError: [Errno 101] Network is unreachable
2018-06-02 03:39:39 ERROR (MainThread) [homeassistant.components.telegram_bot.polling] Cannot connect to host api.telegram.org:443 ssl:True [Temporary failure in name resolution]
2018-06-02 03:39:49 ERROR (MainThread) [homeassistant.components.telegram_bot.polling] Cannot connect to host api.telegram.org:443 ssl:True [Temporary failure in name resolution]
2018-06-02 03:39:59 ERROR (MainThread) [homeassistant.components.telegram_bot.polling] Cannot connect to host api.telegram.org:443 ssl:True [Temporary failure in name resolution]
2018-06-02 03:40:09 ERROR (MainThread) [homeassistant.components.telegram_bot.polling] Cannot connect to host api.telegram.org:443 ssl:True [Temporary failure in name resolution]
2018-06-02 03:40:10 ERROR (MainThread) [homeassistant.helpers.entity] Update for binary_sensor.door_window_sensor_158d000200a8cd fails
Traceback (most recent call last):
  File "/srv/homeassistant/lib/python3.5/site-packages/homeassistant/helpers/entity.py", line 204, in async_update_ha_state
    yield from self.async_device_update()
  File "/srv/homeassistant/lib/python3.5/site-packages/homeassistant/helpers/entity.py", line 327, in async_device_update
    yield from self.hass.async_add_job(self.update)
  File "/usr/lib/python3.5/asyncio/futures.py", line 380, in __iter__
    yield self  # This tells Task to wait for completion.
  File "/usr/lib/python3.5/asyncio/tasks.py", line 304, in _wakeup
    future.result()
  File "/usr/lib/python3.5/asyncio/futures.py", line 293, in result
    raise self._exception
  File "/usr/lib/python3.5/concurrent/futures/thread.py", line 55, in run
    result = self.fn(*self.args, **self.kwargs)
  File "/srv/homeassistant/lib/python3.5/site-packages/homeassistant/components/binary_sensor/xiaomi_aqara.py", line 90, in update
    self._get_from_hub(self._sid)
  File "/srv/homeassistant/lib/python3.5/site-packages/xiaomi_gateway/__init__.py", line 362, in get_from_hub
    resp = self._send_cmd(cmd, "read_ack") if int(self.proto[0:1]) == 1 else self._send_cmd(cmd, "read_rsp")
  File "/srv/homeassistant/lib/python3.5/site-packages/xiaomi_gateway/__init__.py", line 295, in _send_cmd
    self._socket.sendto(cmd.encode(), (self.ip_adress, self.port))
OSError: [Errno 101] Network is unreachable
2018-06-02 03:40:10 ERROR (MainThread) [homeassistant.helpers.entity] Update for binary_sensor.door_window_sensor_158d0001bf4ca9 fails
Traceback (most recent call last):
  File "/srv/homeassistant/lib/python3.5/site-packages/homeassistant/helpers/entity.py", line 204, in async_update_ha_state
    yield from self.async_device_update()
  File "/srv/homeassistant/lib/python3.5/site-packages/homeassistant/helpers/entity.py", line 327, in async_device_update
    yield from self.hass.async_add_job(self.update)
  File "/usr/lib/python3.5/asyncio/futures.py", line 380, in __iter__
    yield self  # This tells Task to wait for completion.
  File "/usr/lib/python3.5/asyncio/tasks.py", line 304, in _wakeup
    future.result()
  File "/usr/lib/python3.5/asyncio/futures.py", line 293, in result
    raise self._exception
  File "/usr/lib/python3.5/concurrent/futures/thread.py", line 55, in run
    result = self.fn(*self.args, **self.kwargs)
  File "/srv/homeassistant/lib/python3.5/site-packages/homeassistant/components/binary_sensor/xiaomi_aqara.py", line 90, in update
    self._get_from_hub(self._sid)
  File "/srv/homeassistant/lib/python3.5/site-packages/xiaomi_gateway/__init__.py", line 362, in get_from_hub
    resp = self._send_cmd(cmd, "read_ack") if int(self.proto[0:1]) == 1 else self._send_cmd(cmd, "read_rsp")
  File "/srv/homeassistant/lib/python3.5/site-packages/xiaomi_gateway/__init__.py", line 295, in _send_cmd
    self._socket.sendto(cmd.encode(), (self.ip_adress, self.port))
OSError: [Errno 101] Network is unreachable
2018-06-02 03:40:19 ERROR (MainThread) [homeassistant.components.telegram_bot.polling] Cannot connect to host api.telegram.org:443 ssl:True [Temporary failure in name resolution]
2018-06-02 03:41:10 ERROR (MainThread) [homeassistant.components.telegram_bot.polling] wrong status 409
2018-06-02 04:08:56 ERROR (Thread-10) [xiaomi_gateway] Got error element in data {"error":"Invalid key"}
2018-06-02 04:09:20 ERROR (Thread-21) [xiaomi_gateway] Got error element in data {"error":"Invalid key"}
2018-06-02 05:08:56 ERROR (Thread-11) [xiaomi_gateway] Got error element in data {"error":"Invalid key"}
2018-06-02 05:14:09 ERROR (MainThread) [homeassistant.components.sensor.template] Could not render template Xiaomi Button 1: UndefinedError: 'mappingproxy object' has no attribute 'battery_level'
2018-06-02 05:18:44 ERROR (MainThread) [homeassistant.components.sensor.template] Could not render template Xiaomi Basement Motion Sensor: UndefinedError: 'mappingproxy object' has no attribute 'battery_level'
2018-06-02 05:20:37 ERROR (MainThread) [homeassistant.components.sensor.template] Could not render template Xiaomi Garage Motion Sensor: UndefinedError: 'mappingproxy object' has no attribute 'battery_level'
2018-06-02 05:26:49 ERROR (MainThread) [homeassistant.components.sensor.template] Could not render template Xiaomi Main Door Sensor: UndefinedError: 'mappingproxy object' has no attribute 'battery_level'
2018-06-02 05:34:03 ERROR (MainThread) [homeassistant.components.sensor.template] Could not render template Xiaomi Entrance Motion Sensor: UndefinedError: 'mappingproxy object' has no attribute 'battery_level'
2018-06-02 05:48:00 ERROR (MainThread) [homeassistant.components.shell_command] Error running command: `ssh pi@homeserver sudo systemctl restart home-assistant@homeassistant`, return code: -15
NoneType: None
2018-06-02 14:13:30 ERROR (Thread-11) [xiaomi_gateway] Cannot connect to Gateway
2018-06-02 14:13:30 ERROR (Thread-11) [xiaomi_gateway] No data in response from hub None
2018-06-02 16:13:48 ERROR (Thread-2) [xiaomi_gateway] Cannot connect to Gateway
2018-06-02 16:13:48 ERROR (Thread-2) [xiaomi_gateway] No data in response from hub None
2018-06-02 20:07:46 ERROR (Thread-15) [xiaomi_gateway] Cannot connect to Gateway
2018-06-02 20:07:46 ERROR (Thread-15) [xiaomi_gateway] No data in response from hub None
2018-06-02 21:16:06 ERROR (MainThread) [homeassistant.components.telegram_bot.polling] wrong status 502
